{"uuid": "5d986e1b-ec73-4304-a021-f9f4b833365e", "children": ["126afea7-0fca-40c9-91f8-f9fbf649ae3b"], "befores": [{"name": "log_on_failure", "status": "passed", "start": 1707975115003, "stop": 1707975115004}], "afters": [{"name": "log_on_failure::0", "status": "broken", "statusDetails": {"message": "selenium.common.exceptions.NoSuchWindowException: Message: no such window: target window already closed\nfrom unknown error: web view not found\n  (Session info: chrome=121.0.6167.160)\nStacktrace:\n#0 0x564d02d8cd93 <unknown>\n#1 0x564d02a70337 <unknown>\n#2 0x564d02a46a18 <unknown>\n#3 0x564d02ae6ead <unknown>\n#4 0x564d02afca95 <unknown>\n#5 0x564d02ade1e3 <unknown>\n#6 0x564d02aae135 <unknown>\n#7 0x564d02aaf13e <unknown>\n#8 0x564d02d50e4b <unknown>\n#9 0x564d02d54dfa <unknown>\n#10 0x564d02d3d6d5 <unknown>\n#11 0x564d02d55a6f <unknown>\n#12 0x564d02d2169f <unknown>\n#13 0x564d02d7a098 <unknown>\n#14 0x564d02d7a262 <unknown>\n#15 0x564d02d8bf34 <unknown>\n#16 0x7f2c7ee94ac3 <unknown>\n\n", "trace": "  File \"/home/shashi/PycharmProjects/pythonSelenium/.venv/lib/python3.10/site-packages/allure_commons/_allure.py\", line 221, in __call__\n    return self._fixture_function(*args, **kwargs)\n  File \"/home/shashi/PycharmProjects/pythonSelenium/.venv/lib/python3.10/site-packages/_pytest/fixtures.py\", line 932, in _teardown_yield_fixture\n    next(it)\n  File \"/home/shashi/PycharmProjects/pythonSelenium/testCases/conftest.py\", line 43, in log_on_failure\n    allure.attach(driver.get_screenshot_as_png(), name='failed_test', attachment_type=AttachmentType.PNG)\n  File \"/home/shashi/PycharmProjects/pythonSelenium/.venv/lib/python3.10/site-packages/selenium/webdriver/remote/webdriver.py\", line 832, in get_screenshot_as_png\n    return b64decode(self.get_screenshot_as_base64().encode(\"ascii\"))\n  File \"/home/shashi/PycharmProjects/pythonSelenium/.venv/lib/python3.10/site-packages/selenium/webdriver/remote/webdriver.py\", line 843, in get_screenshot_as_base64\n    return self.execute(Command.SCREENSHOT)[\"value\"]\n  File \"/home/shashi/PycharmProjects/pythonSelenium/.venv/lib/python3.10/site-packages/selenium/webdriver/remote/webdriver.py\", line 347, in execute\n    self.error_handler.check_response(response)\n  File \"/home/shashi/PycharmProjects/pythonSelenium/.venv/lib/python3.10/site-packages/selenium/webdriver/remote/errorhandler.py\", line 229, in check_response\n    raise exception_class(message, screen, stacktrace)\n"}, "start": 1707975115071, "stop": 1707975115075}], "start": 1707975115003, "stop": 1707975115076}