{"uuid": "15b1bb90-8e7a-4067-b82e-622fce8f760a", "children": ["0aa500d2-3baf-40e7-9dc2-82d580cbf24a"], "befores": [{"name": "log_on_failure", "status": "passed", "start": 1707975107965, "stop": 1707975107965}], "afters": [{"name": "log_on_failure::0", "status": "broken", "statusDetails": {"message": "selenium.common.exceptions.NoSuchWindowException: Message: no such window: target window already closed\nfrom unknown error: web view not found\n  (Session info: chrome=121.0.6167.160)\nStacktrace:\n#0 0x555fa463ed93 <unknown>\n#1 0x555fa4322337 <unknown>\n#2 0x555fa42f8a18 <unknown>\n#3 0x555fa4398ead <unknown>\n#4 0x555fa43aea95 <unknown>\n#5 0x555fa43901e3 <unknown>\n#6 0x555fa4360135 <unknown>\n#7 0x555fa436113e <unknown>\n#8 0x555fa4602e4b <unknown>\n#9 0x555fa4606dfa <unknown>\n#10 0x555fa45ef6d5 <unknown>\n#11 0x555fa4607a6f <unknown>\n#12 0x555fa45d369f <unknown>\n#13 0x555fa462c098 <unknown>\n#14 0x555fa462c262 <unknown>\n#15 0x555fa463df34 <unknown>\n#16 0x7f8446294ac3 <unknown>\n\n", "trace": "  File \"/home/shashi/PycharmProjects/pythonSelenium/.venv/lib/python3.10/site-packages/allure_commons/_allure.py\", line 221, in __call__\n    return self._fixture_function(*args, **kwargs)\n  File \"/home/shashi/PycharmProjects/pythonSelenium/.venv/lib/python3.10/site-packages/_pytest/fixtures.py\", line 932, in _teardown_yield_fixture\n    next(it)\n  File \"/home/shashi/PycharmProjects/pythonSelenium/testCases/conftest.py\", line 43, in log_on_failure\n    allure.attach(driver.get_screenshot_as_png(), name='failed_test', attachment_type=AttachmentType.PNG)\n  File \"/home/shashi/PycharmProjects/pythonSelenium/.venv/lib/python3.10/site-packages/selenium/webdriver/remote/webdriver.py\", line 832, in get_screenshot_as_png\n    return b64decode(self.get_screenshot_as_base64().encode(\"ascii\"))\n  File \"/home/shashi/PycharmProjects/pythonSelenium/.venv/lib/python3.10/site-packages/selenium/webdriver/remote/webdriver.py\", line 843, in get_screenshot_as_base64\n    return self.execute(Command.SCREENSHOT)[\"value\"]\n  File \"/home/shashi/PycharmProjects/pythonSelenium/.venv/lib/python3.10/site-packages/selenium/webdriver/remote/webdriver.py\", line 347, in execute\n    self.error_handler.check_response(response)\n  File \"/home/shashi/PycharmProjects/pythonSelenium/.venv/lib/python3.10/site-packages/selenium/webdriver/remote/errorhandler.py\", line 229, in check_response\n    raise exception_class(message, screen, stacktrace)\n"}, "start": 1707975108000, "stop": 1707975108009}], "start": 1707975107965, "stop": 1707975108009}